Workbook

Sheet Demographics
A1: subject_id | B1: date | C1: condition | D1: age | E1: education | F1: gender | G1: income | H1: race | I1: ethnicity | J1: parent | K1: toddler_interaction | L1: toddler_int_frequency
A2: TTA_001 | B2: {=_xlfn.XLOOKUP(A2,Counterbalances!C2:C176,Counterbalances!D2:E176)} -> 45693 | C2: child | D2: 18 | E2: some college | F2: female | G2: 40 - 75 | H2: african-american | I2: non-hispanic | J2: no | K2: yes | L2: monthly
A3: TTA_002 | B3: {=_xlfn.XLOOKUP(A3,Counterbalances!C3:C177,Counterbalances!D3:E177)} -> 45693 | C3: peer | D3: 18 | E3: high school graduate | F3: female | G3: >150 | H3: african-american | I3: non-hispanic | J3: no | K3: yes | L3: monthly
A4: TTA_003 | B4: {=_xlfn.XLOOKUP(A4,Counterbalances!C4:C178,Counterbalances!D4:E178)} -> 45693 | C4: peer | D4: 18 | E4: high school graduate | F4: female | G4: 75 - 150 | H4: white | I4: non-hispanic | J4: no | K4: yes | L4: rare
A5: TTA_004 | B5: {=_xlfn.XLOOKUP(A5,Counterbalances!C5:C179,Counterbalances!D5:E179)} -> 45693 | C5: short | D5: 20 | E5: associates | F5: female | G5: <20 | H5: white | I5: non-hispanic | J5: no | K5: yes | L5: weekly
A6: TTA_005 | B6: {=_xlfn.XLOOKUP(A6,Counterbalances!C6:C180,Counterbalances!D6:E180)} -> 45693 | C6: short | D6: 19 | E6: some college | F6: female | G6: 40 - 75 | H6: white | I6: non-hispanic | J6: no | K6: no | L6: rare
A7: TTA_006 | B7: {=_xlfn.XLOOKUP(A7,Counterbalances!C7:C181,Counterbalances!D7:E181)} -> 45693 | C7: creative | E7: high school graduate | F7: female | G7: 75 - 150 | H7: white | I7: hispanic | J7: no | K7: yes | L7: monthly
A8: TTA_007 | B8: {=_xlfn.XLOOKUP(A8,Counterbalances!C8:C182,Counterbalances!D8:E182)} -> 45693 | C8: creative | D8: 22 | E8: high school graduate | F8: female | G8: 75 - 150 | H8: african-american | I8: non-hispanic | J8: no | K8: yes | L8: monthly
A9: TTA_008 | B9: {=_xlfn.XLOOKUP(A9,Counterbalances!C9:C183,Counterbalances!D9:E183)} -> 45694 | C9: child | D9: 18 | E9: high school graduate | F9: female | G9: <20 | H9: african-american | I9: non-hispanic | J9: no | K9: yes | L9: monthly
A10: TTA_009 | B10: {=_xlfn.XLOOKUP(A10,Counterbalances!C10:C184,Counterbalances!D10:E184)} -> 45694 | C10: child | D10: 20 | E10: some college | F10: female | G10: >150 | H10: white/asian | I10: non-hispanic | J10: no | K10: yes | L10: rare
A11: TTA_010 | B11: {=_xlfn.XLOOKUP(A11,Counterbalances!C11:C185,Counterbalances!D11:E185)} -> 45699 | C11: peer | D11: 19 | E11: high school graduate | F11: female | G11: 75 - 150 | H11: african-american | I11: non-hispanic | J11: no | K11: yes | L11: few/week
A12: TTA_011 | B12: {=_xlfn.XLOOKUP(A12,Counterbalances!C12:C186,Counterbalances!D12:E186)} -> 45699 | C12: peer | D12: 21 | E12: some college | F12: female | G12: 75 - 150 | H12: white | I12: non-hispanic | J12: no | K12: yes | L12: monthly
A13: TTA_012 | B13: {=_xlfn.XLOOKUP(A13,Counterbalances!C13:C187,Counterbalances!D13:E187)} -> 45699 | C13: short | D13: 20 | E13: associates | F13: female | G13: 20 - 40 | H13: african-american | I13: non-hispanic | J13: no | K13: yes | L13: rare
A14: TTA_013 | B14: {=_xlfn.XLOOKUP(A14,Counterbalances!C14:C188,Counterbalances!D14:E188)} -> 45699 | C14: creative | D14: 18 | E14: high school graduate | F14: female | G14: <20 | H14: african-american | I14: non-hispanic | J14: no | K14: no | L14: rare
A15: TTA_014 | B15: {=_xlfn.XLOOKUP(A15,Counterbalances!C15:C189,Counterbalances!D15:E189)} -> 45699 | C15: child | D15: 20 | E15: high school graduate | F15: female | G15: 20 - 40 | H15: asian | I15: non-hispanic | J15: no | K15: yes | L15: daily
A16: TTA_015 | B16: {=_xlfn.XLOOKUP(A16,Counterbalances!C16:C190,Counterbalances!D16:E190)} -> 45699 | C16: child | D16: 20 | E16: some college | F16: female | G16: 40 - 75 | H16: other | I16: hispanic | J16: no | K16: no | L16: never
A17: TTA_016 | B17: {=_xlfn.XLOOKUP(A17,Counterbalances!C17:C191,Counterbalances!D17:E191)} -> 45700 | C17: short | D17: 19 | E17: high school graduate | F17: female | G17: 75 - 150 | H17: african-american | I17: non-hispanic | J17: no | K17: yes | L17: monthly
A18: TTA_017 | B18: {=_xlfn.XLOOKUP(A18,Counterbalances!C18:C192,Counterbalances!D18:E192)} -> 45700 | C18: short | D18: 18 | E18: some college | F18: female | G18: <20 | H18: african-american | I18: hispanic | J18: no | K18: yes | L18: monthly
A19: TTA_018 | B19: {=_xlfn.XLOOKUP(A19,Counterbalances!C19:C193,Counterbalances!D19:E193)} -> 45700 | C19: creative | D19: 19 | E19: high school graduate | F19: female | G19: 20 - 40 | H19: other | I19: hispanic | J19: no | K19: yes | L19: monthly
... A41: TTA_040 | B41: {=_xlfn.XLOOKUP(A41,Counterbalances!C41:C215,Counterbalances!D41:E215)} -> 45702 | C41: peer | D41: 19 | E41: high school graduate | F41: male | G41: 75 - 150 | H41: white | I41: non-hispanic | J41: no | K41: yes | L41: few/week
A42: TTA_041 | B42: {=_xlfn.XLOOKUP(A42,Counterbalances!C42:C216,Counterbalances!D42:E216)} -> 45702 | C42: short | D42: 19 | E42: some college | F42: female | H42: white | I42: ND | J42: no | K42: no | L42: rare
A43: TTA_042 | B43: {=_xlfn.XLOOKUP(A43,Counterbalances!C43:C217,Counterbalances!D43:E217)} -> 45702 | C43: short | D43: 21 | E43: some college | F43: male | G43: <20 | H43: white | I43: hispanic | J43: no | K43: no | L43: never
A44: TTA_043 | B44: {=_xlfn.XLOOKUP(A44,Counterbalances!C44:C218,Counterbalances!D44:E218)} -> 45705 | C44: child | D44: 20 | E44: some college | F44: female | G44: 40 - 75 | H44: asian | I44: non-hispanic | J44: no | K44: no | L44: rare
A45: TTA_044 | B45: {=_xlfn.XLOOKUP(A45,Counterbalances!C45:C219,Counterbalances!D45:E219)} -> 45705 | C45: child | D45: 19 | E45: high school graduate | F45: female | G45: 75 - 150 | H45: other | I45: hispanic | J45: no | K45: yes | L45: few/week
A46: TTA_045 | B46: {=_xlfn.XLOOKUP(A46,Counterbalances!C46:C220,Counterbalances!D46:E220)} -> 45705 | C46: peer | D46: 20 | E46: high school graduate | F46: female | G46: 75 - 150 | H46: white | I46: non-hispanic | J46: no | K46: no | L46: never
A47: TTA_046 | B47: {=_xlfn.XLOOKUP(A47,Counterbalances!C47:C221,Counterbalances!D47:E221)} -> 45705 | C47: peer | D47: 18 | E47: some college | F47: female | G47: <20 | H47: african-american | I47: non-hispanic | J47: no | K47: yes | L47: rare
A48: TTA_047 | B48: {=_xlfn.XLOOKUP(A48,Counterbalances!C48:C222,Counterbalances!D48:E222)} -> 45706 | C48: short | D48: 18 | E48: some college | F48: female | G48: 75 - 150 | H48: white | I48: non-hispanic | J48: no | K48: yes | L48: monthly
A49: TTA_048 | B49: {=_xlfn.XLOOKUP(A49,Counterbalances!C49:C223,Counterbalances!D49:E223)} -> 45706 | C49: short | D49: 19 | E49: high school graduate | F49: female | G49: 75 - 150 | H49: african-american | I49: non-hispanic | J49: no | K49: yes | L49: rare
A50: TTA_049 | B50: {=_xlfn.XLOOKUP(A50,Counterbalances!C50:C224,Counterbalances!D50:E224)} -> 45706 | C50: creative | D50: 19 | E50: high school graduate | F50: female | G50: <20 | H50: african-american | I50: non-hispanic | J50: no | K50: yes | L50: rare
A51: TTA_050 | B51: {=_xlfn.XLOOKUP(A51,Counterbalances!C51:C225,Counterbalances!D51:E225)} -> 45706 | C51: creative | D51: 20 | E51: some college | F51: female | G51: <20 | H51: african-american | I51: non-hispanic | J51: no | K51: no | L51: rare
A52: TTA_051 | B52: {=_xlfn.XLOOKUP(A52,Counterbalances!C52:C226,Counterbalances!D52:E226)} -> 45707 | C52: child | D52: 20 | E52: high school graduate | F52: female | G52: >150 | H52: white | I52: non-hispanic | J52: no | K52: yes | L52: weekly
A53: TTA_052 | B53: {=_xlfn.XLOOKUP(A53,Counterbalances!C53:C227,Counterbalances!D53:E227)} -> 45707 | C53: child | D53: 19 | E53: high school graduate | F53: female | G53: 75 - 150 | H53: african-american | I53: hispanic | J53: no | K53: yes | L53: rare
A54: TTA_053 | B54: {=_xlfn.XLOOKUP(A54,Counterbalances!C54:C228,Counterbalances!D54:E228)} -> 45707 | C54: short | D54: 19 | E54: some college | F54: male | G54: 75 - 150 | H54: asian | I54: non-hispanic | J54: no | K54: yes | L54: rare
... A83: TTA_082 | B83: {=_xlfn.XLOOKUP(A83,Counterbalances!C83:C257,Counterbalances!D83:E257)} -> 45713 | C83: short | D83: 18 | E83: some college | F83: female | G83: 40 - 75 | H83: african-american/asian | I83: hispanic | J83: no | K83: yes | L83: rare
A84: TTA_083 | B84: {=_xlfn.XLOOKUP(A84,Counterbalances!C84:C258,Counterbalances!D84:E258)} -> 45713 | C84: creative | D84: 18 | E84: high school graduate | F84: male | H84: asian | I84: non-hispanic | J84: no | K84: yes | L84: rare
A85: TTA_084 | B85: {=_xlfn.XLOOKUP(A85,Counterbalances!C85:C259,Counterbalances!D85:E259)} -> 45713 | C85: creative | D85: 20 | E85: some college | F85: male | G85: 75 - 150 | H85: white | I85: non-hispanic | J85: no | K85: yes | L85: monthly
A86: TTA_085 | B86: {=_xlfn.XLOOKUP(A86,Counterbalances!C86:C260,Counterbalances!D86:E260)} -> 45713 | C86: child | D86: 18 | E86: some college | F86: female | G86: >150 | H86: white | I86: non-hispanic | J86: no | K86: yes | L86: monthly
A87: TTA_086 | B87: {=_xlfn.XLOOKUP(A87,Counterbalances!C87:C261,Counterbalances!D87:E261)} -> 45713 | C87: child | D87: 18 | E87: some college | F87: female | G87: 75 - 150 | H87: white | I87: hispanic | J87: no | K87: yes | L87: weekly
A88: TTA_087 | B88: {=_xlfn.XLOOKUP(A88,Counterbalances!C88:C262,Counterbalances!D88:E262)} -> 45714 | C88: peer | D88: 19 | E88: some college | F88: male | G88: >150 | H88: white | I88: non-hispanic | J88: no | K88: yes | L88: monthly
A89: TTA_088 | B89: {=_xlfn.XLOOKUP(A89,Counterbalances!C89:C263,Counterbalances!D89:E263)} -> 45714 | C89: short | D89: 19 | E89: high school graduate | F89: male | G89: 40 - 75 | H89: white | I89: non-hispanic | J89: no | K89: yes | L89: rare
...

Sheet Counterbalances
A1: Session | B1: Computer ID (A or B) | C1: PPID | D1: Date | E1: Condition | F1: Completed | G1: PointsAwarded | H1: NoShow | I1: NoSignup | J1: child_count | K1: peer_count | L1: short_count | M1: creative_count
A2: 1 | B2: B | C2: TTA_001 | D2: 45693 | E2: child | F2: TRUE | G2: TRUE | H2: FALSE | I2: FALSE | J2: =IF(AND(E2="child",F2=TRUE), 1,0) -> 1 | K2: =IF(AND(E2="peer",F2=TRUE), 1,0) -> 0 | L2: =IF(AND(E2="short",F2=TRUE), 1,0) -> 0 | M2: =IF(AND(E2="creative",F2=TRUE), 1,0) -> 0
A3: 1 | B3: A | D3: 45693 | E3: child | F3: FALSE | G3: FALSE | H3: TRUE | I3: FALSE | J3: =IF(AND(E3="child",F3=TRUE), 1,0) -> 0 | K3: =IF(AND(E3="peer",F3=TRUE), 1,0) -> 0 | L3: =IF(AND(E3="short",F3=TRUE), 1,0) -> 0 | M3: =IF(AND(E3="creative",F3=TRUE), 1,0) -> 0
A4: =A2+1 -> 2 | B4: B | C4: TTA_002 | D4: 45693 | E4: peer | F4: TRUE | G4: TRUE | H4: FALSE | I4: FALSE | J4: =IF(AND(E4="child",F4=TRUE), 1,0) -> 0 | K4: =IF(AND(E4="peer",F4=TRUE), 1,0) -> 1 | L4: =IF(AND(E4="short",F4=TRUE), 1,0) -> 0 | M4: =IF(AND(E4="creative",F4=TRUE), 1,0) -> 0
A5: =A3+1 -> 2 | B5: A | C5: TTA_003 | D5: 45693 | E5: peer | F5: TRUE | G5: TRUE | H5: FALSE | I5: FALSE | J5: =IF(AND(E5="child",F5=TRUE), 1,0) -> 0 | K5: =IF(AND(E5="peer",F5=TRUE), 1,0) -> 1 | L5: =IF(AND(E5="short",F5=TRUE), 1,0) -> 0 | M5: =IF(AND(E5="creative",F5=TRUE), 1,0) -> 0
A6: =A4+1 -> 3 | B6: B | C6: TTA_004 | D6: 45693 | E6: short | F6: TRUE | G6: TRUE | H6: FALSE | I6: FALSE | J6: =IF(AND(E6="child",F6=TRUE), 1,0) -> 0 | K6: =IF(AND(E6="peer",F6=TRUE), 1,0) -> 0 | L6: =IF(AND(E6="short",F6=TRUE), 1,0) -> 1 | M6: =IF(AND(E6="creative",F6=TRUE), 1,0) -> 0
A7: =A5+1 -> 3 | B7: A | C7: TTA_005 | D7: 45693 | E7: short | F7: TRUE | G7: TRUE | H7: FALSE | I7: FALSE | J7: =IF(AND(E7="child",F7=TRUE), 1,0) -> 0 | K7: =IF(AND(E7="peer",F7=TRUE), 1,0) -> 0 | L7: =IF(AND(E7="short",F7=TRUE), 1,0) -> 1 | M7: =IF(AND(E7="creative",F7=TRUE), 1,0) -> 0
A8: =A6+1 -> 4 | B8: B | C8: TTA_006 | D8: 45693 | E8: creative | F8: TRUE | G8: TRUE | H8: FALSE | I8: FALSE | J8: =IF(AND(E8="child",F8=TRUE), 1,0) -> 0 | K8: =IF(AND(E8="peer",F8=TRUE), 1,0) -> 0 | L8: =IF(AND(E8="short",F8=TRUE), 1,0) -> 0 | M8: =IF(AND(E8="creative",F8=TRUE), 1,0) -> 1
A9: =A7+1 -> 4 | B9: A | C9: TTA_007 | D9: 45693 | E9: creative | F9: TRUE | G9: TRUE | H9: FALSE | I9: FALSE | J9: =IF(AND(E9="child",F9=TRUE), 1,0) -> 0 | K9: =IF(AND(E9="peer",F9=TRUE), 1,0) -> 0 | L9: =IF(AND(E9="short",F9=TRUE), 1,0) -> 0 | M9: =IF(AND(E9="creative",F9=TRUE), 1,0) -> 1
A10: =A8+1 -> 5 | B10: B | C10: TTA_008 | D10: 45694 | E10: child | F10: TRUE | G10: TRUE | H10: FALSE | I10: FALSE | J10: =IF(AND(E10="child",F10=TRUE), 1,0) -> 1 | K10: =IF(AND(E10="peer",F10=TRUE), 1,0) -> 0 | L10: =IF(AND(E10="short",F10=TRUE), 1,0) -> 0 | M10: =IF(AND(E10="creative",F10=TRUE), 1,0) -> 0
A11: =A9+1 -> 5 | B11: A | C11: TTA_009 | D11: 45694 | E11: child | F11: TRUE | G11: TRUE | H11: FALSE | I11: FALSE | J11: =IF(AND(E11="child",F11=TRUE), 1,0) -> 1 | K11: =IF(AND(E11="peer",F11=TRUE), 1,0) -> 0 | L11: =IF(AND(E11="short",F11=TRUE), 1,0) -> 0 | M11: =IF(AND(E11="creative",F11=TRUE), 1,0) -> 0
A12: =A10+1 -> 6 | B12: A | C12: TTA_010 | D12: 45699 | E12: peer | F12: TRUE | G12: TRUE | H12: FALSE | I12: FALSE | J12: =IF(AND(E12="child",F12=TRUE), 1,0) -> 0 | K12: =IF(AND(E12="peer",F12=TRUE), 1,0) -> 1 | L12: =IF(AND(E12="short",F12=TRUE), 1,0) -> 0 | M12: =IF(AND(E12="creative",F12=TRUE), 1,0) -> 0
A13: =A11+1 -> 6 | B13: B | C13: TTA_011 | D13: 45699 | E13: peer | F13: TRUE | G13: TRUE | H13: FALSE | I13: FALSE | J13: =IF(AND(E13="child",F13=TRUE), 1,0) -> 0 | K13: =IF(AND(E13="peer",F13=TRUE), 1,0) -> 1 | L13: =IF(AND(E13="short",F13=TRUE), 1,0) -> 0 | M13: =IF(AND(E13="creative",F13=TRUE), 1,0) -> 0
A14: =A12+1 -> 7 | B14: A | D14: 45699 | E14: short | F14: FALSE | G14: FALSE | H14: FALSE | I14: TRUE | J14: =IF(AND(E14="child",F14=TRUE), 1,0) -> 0 | K14: =IF(AND(E14="peer",F14=TRUE), 1,0) -> 0 | L14: =IF(AND(E14="short",F14=TRUE), 1,0) -> 0 | M14: =IF(AND(E14="creative",F14=TRUE), 1,0) -> 0
A15: =A13+1 -> 7 | B15: B | C15: TTA_012 | D15: 45699 | E15: short | F15: TRUE | G15: TRUE | H15: FALSE | I15: FALSE | J15: =IF(AND(E15="child",F15=TRUE), 1,0) -> 0 | K15: =IF(AND(E15="peer",F15=TRUE), 1,0) -> 0 | L15: =IF(AND(E15="short",F15=TRUE), 1,0) -> 1 | M15: =IF(AND(E15="creative",F15=TRUE), 1,0) -> 0
A16: =A14+1 -> 8 | B16: B | C16: TTA_013 | D16: 45699 | E16: creative | F16: TRUE | G16: FALSE | H16: FALSE | I16: FALSE | J16: =IF(AND(E16="child",F16=TRUE), 1,0) -> 0 | K16: =IF(AND(E16="peer",F16=TRUE), 1,0) -> 0 | L16: =IF(AND(E16="short",F16=TRUE), 1,0) -> 0 | M16: =IF(AND(E16="creative",F16=TRUE), 1,0) -> 1
A17: =A15+1 -> 8 | D17: 45699 | E17: creative | F17: FALSE | G17: FALSE | H17: FALSE | I17: TRUE | J17: =IF(AND(E17="child",F17=TRUE), 1,0) -> 0 | K17: =IF(AND(E17="peer",F17=TRUE), 1,0) -> 0 | L17: =IF(AND(E17="short",F17=TRUE), 1,0) -> 0 | M17: =IF(AND(E17="creative",F17=TRUE), 1,0) -> 0
A18: =A16+1 -> 9 | B18: A | C18: TTA_014 | D18: 45699 | E18: child | F18: TRUE | G18: TRUE | H18: FALSE | I18: FALSE | J18: =IF(AND(E18="child",F18=TRUE), 1,0) -> 1 | K18: =IF(AND(E18="peer",F18=TRUE), 1,0) -> 0 | L18: =IF(AND(E18="short",F18=TRUE), 1,0) -> 0 | M18: =IF(AND(E18="creative",F18=TRUE), 1,0) -> 0
A19: =A17+1 -> 9 | B19: B | C19: TTA_015 | D19: 45699 | E19: child | F19: TRUE | G19: TRUE | H19: FALSE | I19: FALSE | J19: =IF(AND(E19="child",F19=TRUE), 1,0) -> 1 | K19: =IF(AND(E19="peer",F19=TRUE), 1,0) -> 0 | L19: =IF(AND(E19="short",F19=TRUE), 1,0) -> 0 | M19: =IF(AND(E19="creative",F19=TRUE), 1,0) -> 0
A20: =A18+1 -> 10 | D20: 45699 | E20: peer | F20: FALSE | G20: FALSE | H20: TRUE | I20: FALSE | J20: =IF(AND(E20="child",F20=TRUE), 1,0) -> 0 | K20: =IF(AND(E20="peer",F20=TRUE), 1,0) -> 0 | L20: =IF(AND(E20="short",F20=TRUE), 1,0) -> 0 | M20: =IF(AND(E20="creative",F20=TRUE), 1,0) -> 0
A21: =A19+1 -> 10 | D21: 45699 | E21: peer | F21: FALSE | G21: FALSE | H21: FALSE | I21: TRUE | J21: =IF(AND(E21="child",F21=TRUE), 1,0) -> 0 | K21: =IF(AND(E21="peer",F21=TRUE), 1,0) -> 0 | L21: =IF(AND(E21="short",F21=TRUE), 1,0) -> 0 | M21: =IF(AND(E21="creative",F21=TRUE), 1,0) -> 0
A22: =A20+1 -> 11 | B22: A | C22: TTA_016 | D22: 45700 | E22: short | F22: TRUE | G22: TRUE | H22: FALSE | I22: FALSE | J22: =IF(AND(E22="child",F22=TRUE), 1,0) -> 0 | K22: =IF(AND(E22="peer",F22=TRUE), 1,0) -> 0 | L22: =IF(AND(E22="short",F22=TRUE), 1,0) -> 1 | M22: =IF(AND(E22="creative",F22=TRUE), 1,0) -> 0
A23: =A21+1 -> 11 | B23: B | C23: TTA_017 | D23: 45700 | E23: short | F23: TRUE | G23: TRUE | H23: FALSE | I23: FALSE | J23: =IF(AND(E23="child",F23=TRUE), 1,0) -> 0 | K23: =IF(AND(E23="peer",F23=TRUE), 1,0) -> 0 | L23: =IF(AND(E23="short",F23=TRUE), 1,0) -> 1 | M23: =IF(AND(E23="creative",F23=TRUE), 1,0) -> 0
A24: =A22+1 -> 12 | B24: A | C24: TTA_018 | D24: 45700 | E24: creative | F24: TRUE | G24: TRUE | H24: FALSE | I24: FALSE | J24: =IF(AND(E24="child",F24=TRUE), 1,0) -> 0 | K24: =IF(AND(E24="peer",F24=TRUE), 1,0) -> 0 | L24: =IF(AND(E24="short",F24=TRUE), 1,0) -> 0 | M24: =IF(AND(E24="creative",F24=TRUE), 1,0) -> 1
A25: =A23+1 -> 12 | B25: B | C25: TTA_019 | D25: 45700 | E25: creative | F25: TRUE | G25: TRUE | H25: FALSE | I25: FALSE | J25: =IF(AND(E25="child",F25=TRUE), 1,0) -> 0 | K25: =IF(AND(E25="peer",F25=TRUE), 1,0) -> 0 | L25: =IF(AND(E25="short",F25=TRUE), 1,0) -> 0 | M25: =IF(AND(E25="creative",F25=TRUE), 1,0) -> 1
A26: =A24+1 -> 13 | B26: A | C26: TTA_020 | D26: 45700 | E26: child | F26: TRUE | G26: TRUE | H26: FALSE | I26: FALSE | J26: =IF(AND(E26="child",F26=TRUE), 1,0) -> 1 | K26: =IF(AND(E26="peer",F26=TRUE), 1,0) -> 0 | L26: =IF(AND(E26="short",F26=TRUE), 1,0) -> 0 | M26: =IF(AND(E26="creative",F26=TRUE), 1,0) -> 0
A27: =A25+1 -> 13 | B27: B | C27: TTA_021 | D27: 45700 | E27: child | F27: TRUE | G27: TRUE | H27: FALSE | I27: FALSE | J27: =IF(AND(E27="child",F27=TRUE), 1,0) -> 1 | K27: =IF(AND(E27="peer",F27=TRUE), 1,0) -> 0 | L27: =IF(AND(E27="short",F27=TRUE), 1,0) -> 0 | M27: =IF(AND(E27="creative",F27=TRUE), 1,0) -> 0
A28: =A26+1 -> 14 | B28: A | C28: TTA_022 | D28: 45700 | E28: peer | F28: TRUE | G28: TRUE | H28: FALSE | I28: FALSE | J28: =IF(AND(E28="child",F28=TRUE), 1,0) -> 0 | K28: =IF(AND(E28="peer",F28=TRUE), 1,0) -> 1 | L28: =IF(AND(E28="short",F28=TRUE), 1,0) -> 0 | M28: =IF(AND(E28="creative",F28=TRUE), 1,0) -> 0
A29: =A27+1 -> 14 | D29: 45700 | E29: peer | F29: FALSE | G29: FALSE | H29: FALSE | I29: TRUE | J29: =IF(AND(E29="child",F29=TRUE), 1,0) -> 0 | K29: =IF(AND(E29="peer",F29=TRUE), 1,0) -> 0 | L29: =IF(AND(E29="short",F29=TRUE), 1,0) -> 0 | M29: =IF(AND(E29="creative",F29=TRUE), 1,0) -> 0
A30: =A28+1 -> 15 | B30: B | C30: TTA_023 | D30: 45700 | E30: short | F30: TRUE | G30: TRUE | H30: FALSE | I30: FALSE | J30: =IF(AND(E30="child",F30=TRUE), 1,0) -> 0 | K30: =IF(AND(E30="peer",F30=TRUE), 1,0) -> 0 | L30: =IF(AND(E30="short",F30=TRUE), 1,0) -> 1 | M30: =IF(AND(E30="creative",F30=TRUE), 1,0) -> 0
A31: =A29+1 -> 15 | B31: A | C31: TTA_024 | D31: 45700 | E31: short | F31: TRUE | G31: TRUE | H31: FALSE | I31: FALSE | J31: =IF(AND(E31="child",F31=TRUE), 1,0) -> 0 | K31: =IF(AND(E31="peer",F31=TRUE), 1,0) -> 0 | L31: =IF(AND(E31="short",F31=TRUE), 1,0) -> 1 | M31: =IF(AND(E31="creative",F31=TRUE), 1,0) -> 0
A32: =A30+1 -> 16 | B32: B | C32: TTA_025 | D32: 45700 | E32: creative | F32: TRUE | G32: TRUE | H32: FALSE | I32: FALSE | J32: =IF(AND(E32="child",F32=TRUE), 1,0) -> 0 | K32: =IF(AND(E32="peer",F32=TRUE), 1,0) -> 0 | L32: =IF(AND(E32="short",F32=TRUE), 1,0) -> 0 | M32: =IF(AND(E32="creative",F32=TRUE), 1,0) -> 1
A33: =A31+1 -> 16 | E33: creative | F33: FALSE | G33: FALSE | H33: FALSE | I33: TRUE | J33: =IF(AND(E33="child",F33=TRUE), 1,0) -> 0 | K33: =IF(AND(E33="peer",F33=TRUE), 1,0) -> 0 | L33: =IF(AND(E33="short",F33=TRUE), 1,0) -> 0 | M33: =IF(AND(E33="creative",F33=TRUE), 1,0) -> 0
A34: =A32+1 -> 17 | B34: B | C34: TTA_026 | D34: 45700 | E34: child | F34: TRUE | G34: TRUE | H34: FALSE | I34: FALSE | J34: =IF(AND(E34="child",F34=TRUE), 1,0) -> 1 | K34: =IF(AND(E34="peer",F34=TRUE), 1,0) -> 0 | L34: =IF(AND(E34="short",F34=TRUE), 1,0) -> 0 | M34: =IF(AND(E34="creative",F34=TRUE), 1,0) -> 0
A35: =A33+1 -> 17 | B35: A | C35: TTA_027 | D35: 45700 | E35: child | F35: TRUE | G35: TRUE | H35: FALSE | I35: FALSE | J35: =IF(AND(E35="child",F35=TRUE), 1,0) -> 1 | K35: =IF(AND(E35="peer",F35=TRUE), 1,0) -> 0 | L35: =IF(AND(E35="short",F35=TRUE), 1,0) -> 0 | M35: =IF(AND(E35="creative",F35=TRUE), 1,0) -> 0
A36: =A34+1 -> 18 | B36: A | C36: TTA_028 | D36: 45701 | E36: peer | F36: TRUE | G36: TRUE | H36: FALSE | I36: FALSE | J36: =IF(AND(E36="child",F36=TRUE), 1,0) -> 0 | K36: =IF(AND(E36="peer",F36=TRUE), 1,0) -> 1 | L36: =IF(AND(E36="short",F36=TRUE), 1,0) -> 0 | M36: =IF(AND(E36="creative",F36=TRUE), 1,0) -> 0
A37: =A35+1 -> 18 | B37: B | C37: TTA_029 | D37: 45701 | E37: peer | F37: TRUE | G37: TRUE | H37: FALSE | I37: FALSE | J37: =IF(AND(E37="child",F37=TRUE), 1,0) -> 0 | K37: =IF(AND(E37="peer",F37=TRUE), 1,0) -> 1 | L37: =IF(AND(E37="short",F37=TRUE), 1,0) -> 0 | M37: =IF(AND(E37="creative",F37=TRUE), 1,0) -> 0
A38: =A36+1 -> 19 | B38: A | C38: TTA_030 | D38: 45701 | E38: short | F38: TRUE | G38: TRUE | H38: FALSE | I38: FALSE | J38: =IF(AND(E38="child",F38=TRUE), 1,0) -> 0 | K38: =IF(AND(E38="peer",F38=TRUE), 1,0) -> 0 | L38: =IF(AND(E38="short",F38=TRUE), 1,0) -> 1 | M38: =IF(AND(E38="creative",F38=TRUE), 1,0) -> 0
A39: =A37+1 -> 19 | B39: B | C39: TTA_031 | D39: 45701 | E39: short | F39: TRUE | G39: TRUE | H39: FALSE | I39: FALSE | J39: =IF(AND(E39="child",F39=TRUE), 1,0) -> 0 | K39: =IF(AND(E39="peer",F39=TRUE), 1,0) -> 0 | L39: =IF(AND(E39="short",F39=TRUE), 1,0) -> 1 | M39: =IF(AND(E39="creative",F39=TRUE), 1,0) -> 0
A40: =A38+1 -> 20 | B40: B | C40: TTA_032 | D40: 45702 | E40: creative | F40: TRUE | G40: TRUE | H40: FALSE | I40: FALSE | J40: =IF(AND(E40="child",F40=TRUE), 1,0) -> 0 | K40: =IF(AND(E40="peer",F40=TRUE), 1,0) -> 0 | L40: =IF(AND(E40="short",F40=TRUE), 1,0) -> 0 | M40: =IF(AND(E40="creative",F40=TRUE), 1,0) -> 1
...
